wandb: Currently logged in as: gjyspliter. Use `wandb login --relogin` to force relogin
wandb: - Waiting for wandb.init()...wandb: \ Waiting for wandb.init()...wandb: Tracking run with wandb version 0.13.11
wandb: Run data is saved locally in /Users/goojy/Documents/Project/Graph-GPT/wandb/run-20230309_125147-lfdw5cye
wandb: Run `wandb offline` to turn off syncing.
wandb: Syncing run frosty-wood-2
wandb: ‚≠êÔ∏è View project at https://wandb.ai/gjyspliter/GraphBench
wandb: üöÄ View run at https://wandb.ai/gjyspliter/GraphBench/runs/lfdw5cye
  0%|          | 0/1 [00:00<?, ?it/s]
0it [00:00, ?it/s][A0it [00:47, ?it/s]
  0%|          | 0/1 [00:47<?, ?it/s]
Traceback (most recent call last):
  File "/opt/anaconda3/envs/chatgpt/lib/python3.10/site-packages/urllib3/connection.py", line 174, in _new_conn
    conn = connection.create_connection(
  File "/opt/anaconda3/envs/chatgpt/lib/python3.10/site-packages/urllib3/util/connection.py", line 72, in create_connection
    for res in socket.getaddrinfo(host, port, family, socket.SOCK_STREAM):
  File "/opt/anaconda3/envs/chatgpt/lib/python3.10/socket.py", line 955, in getaddrinfo
    for res in _socket.getaddrinfo(host, port, family, type, proto, flags):
socket.gaierror: [Errno 8] nodename nor servname provided, or not known

During handling of the above exception, another exception occurred:

Traceback (most recent call last):
  File "/opt/anaconda3/envs/chatgpt/lib/python3.10/site-packages/urllib3/connectionpool.py", line 703, in urlopen
    httplib_response = self._make_request(
  File "/opt/anaconda3/envs/chatgpt/lib/python3.10/site-packages/urllib3/connectionpool.py", line 386, in _make_request
    self._validate_conn(conn)
  File "/opt/anaconda3/envs/chatgpt/lib/python3.10/site-packages/urllib3/connectionpool.py", line 1042, in _validate_conn
    conn.connect()
  File "/opt/anaconda3/envs/chatgpt/lib/python3.10/site-packages/urllib3/connection.py", line 358, in connect
    self.sock = conn = self._new_conn()
  File "/opt/anaconda3/envs/chatgpt/lib/python3.10/site-packages/urllib3/connection.py", line 186, in _new_conn
    raise NewConnectionError(
urllib3.exceptions.NewConnectionError: <urllib3.connection.HTTPSConnection object at 0x13f7c9ea0>: Failed to establish a new connection: [Errno 8] nodename nor servname provided, or not known

During handling of the above exception, another exception occurred:

Traceback (most recent call last):
  File "/opt/anaconda3/envs/chatgpt/lib/python3.10/site-packages/requests/adapters.py", line 489, in send
    resp = conn.urlopen(
  File "/opt/anaconda3/envs/chatgpt/lib/python3.10/site-packages/urllib3/connectionpool.py", line 787, in urlopen
    retries = retries.increment(
  File "/opt/anaconda3/envs/chatgpt/lib/python3.10/site-packages/urllib3/util/retry.py", line 592, in increment
    raise MaxRetryError(_pool, url, error or ResponseError(cause))
urllib3.exceptions.MaxRetryError: HTTPSConnectionPool(host='augloop-cs-test-scus-shared-open-ai-0.openai.azure.com', port=443): Max retries exceeded with url: /openai/deployments/text-davinci-003/completions?api-version=2022-12-01 (Caused by NewConnectionError('<urllib3.connection.HTTPSConnection object at 0x13f7c9ea0>: Failed to establish a new connection: [Errno 8] nodename nor servname provided, or not known'))

During handling of the above exception, another exception occurred:

Traceback (most recent call last):
  File "/Users/goojy/Documents/Project/Graph-GPT/run_experiments.py", line 148, in <module>
    main(args)
  File "/Users/goojy/Documents/Project/Graph-GPT/run_experiments.py", line 115, in main
    response   = requests.post(url=url, headers=headers, data=json.dumps(data))
  File "/opt/anaconda3/envs/chatgpt/lib/python3.10/site-packages/requests/api.py", line 115, in post
    return request("post", url, data=data, json=json, **kwargs)
  File "/opt/anaconda3/envs/chatgpt/lib/python3.10/site-packages/requests/api.py", line 59, in request
    return session.request(method=method, url=url, **kwargs)
  File "/opt/anaconda3/envs/chatgpt/lib/python3.10/site-packages/requests/sessions.py", line 587, in request
    resp = self.send(prep, **send_kwargs)
  File "/opt/anaconda3/envs/chatgpt/lib/python3.10/site-packages/requests/sessions.py", line 701, in send
    r = adapter.send(request, **kwargs)
  File "/opt/anaconda3/envs/chatgpt/lib/python3.10/site-packages/requests/adapters.py", line 565, in send
    raise ConnectionError(e, request=request)
requests.exceptions.ConnectionError: HTTPSConnectionPool(host='augloop-cs-test-scus-shared-open-ai-0.openai.azure.com', port=443): Max retries exceeded with url: /openai/deployments/text-davinci-003/completions?api-version=2022-12-01 (Caused by NewConnectionError('<urllib3.connection.HTTPSConnection object at 0x13f7c9ea0>: Failed to establish a new connection: [Errno 8] nodename nor servname provided, or not known'))
wandb: Waiting for W&B process to finish... (failed 1). Press Control-C to abort syncing.
wandb: üöÄ View run frosty-wood-2 at: https://wandb.ai/gjyspliter/GraphBench/runs/lfdw5cye
wandb: Synced 6 W&B file(s), 0 media file(s), 0 artifact file(s) and 0 other file(s)
wandb: Find logs at: ./wandb/run-20230309_125147-lfdw5cye/logs
